<robot name="Manipulator">
<link name="base_link"/>
<link name="link1"/>
<link name="link2"/>
<link name="link3"/>
<link name="link4"/>
<link name="link5"/>

<joint name="Revolute 1" type="revolute">
<parent link="base_link"/>
<child link="link1"/>
<origin xyz="0 0 14"/>
<axis xyz="0 0 1"/>
</joint>

<joint name="Revolute 3" type="revolute">
<parent link="link1"/>
<child link="link2"/>
<origin xyz="0 0 10"/>
<axis xyz="0 1 0"/>
</joint>

<joint name="Revolute 4" type="revolute">
<parent link="link2"/>
<child link="link3"/>
<origin xyz="0 0 130.266"/>
<axis xyz="0 1 0"/>
</joint>

<joint name="Revolute 5" type="revolute">
<parent link="link3"/>
<child link="link4"/>
<origin xyz="125 0 0"/>
<axis xyz="0 1 0"/>
</joint>

<joint name="Revolute 6" type="revolute">
<parent link="link4"/>
<child link="link5"/>
<origin xyz="0 0 90"/>
<axis xyz="0 0 1"/>
</joint>

</robot>